Workbook

Sheet README
B1: McDonald's (MCD) equity research model - v6
B3: Purpose | C3: Valuation model behind the equity research report: Hold, target $249 (DCF 60% / franchise-heavy comps 40%). Every market input is the official 24-Sep-2026 close.
B4: Model flow | C4: Reference_Data and Historical_5Y -> Forecast -> DCF. Market_WACC and Peers -> Comps -> WACC (bottom-up beta) -> DCF. DCF and Comps -> Valuation (target, rating, sensitivities).
B5: How to use | C5: Change blue-on-yellow assumptions on Forecast, WACC and Valuation; everything else recalculates. Model_Review records every change and why.
B10: Legend
B11: 1,234 | C11: Blue text on yellow = input you type
B12: 1,234 | C12: Black = formula, do not overwrite
B13: 1,234 | C13: Green = direct link to another sheet
C14: Grey = not disclosed for that period
B15: 1,234 | C15: Blue text (no fill) = market data or a figure typed from the source in the note column
B16: Label | C16: Lavender label = changed after the 25-26 Sep reviews (see Model_Review)
B17: Conventions | C17: $ in millions unless stated. Percentages entered as decimals (2.1% = 0.021). Costs, capex, buybacks and dividends entered as positive numbers. Q2 = three months to 30 June; H1 = six months to 30 June.
B18: Data notes | C18: Quarterly totals can differ by $1m from the release because line items are rounded. Q2 systemwide sales ($37bn) and loyalty users (~210m, ~220m) are rounded as disclosed. 2023 special charges are not given in the 2025 10-K.
B20: Tabs (in workbook order)
B21: Historical_5Y | C21: FY2021-FY2025 revenue split, operating income, net income, EPS, D&A, capex, FCF, dividends, debt and leverage.
B22: Historical_Drivers | C22: FY2023-H1 2026 operating drivers (comps, units, systemwide sales, take rates, margins, SG&A, FCF conversion, reported ROIC, leverage) and a GAAP-to-adjusted bridge.
B23: Industry_Evidence | C23: Independent U.S. restaurant traffic data (RMS, Black Box, NRA, BLS, Circana, Placer.ai) and franchisee unit economics from Investor Day.
B24: Market_WACC | C24: MCD share price, shares, market cap, raw beta, 10-year Treasury and dividend (24-Sep-2026 close); source multiples and an EV cross-check.
B25: Peers | C25: YUM, QSR, SBUX, CMG, DPZ at the 24-Sep close: market cap, EV, P/E, EV/EBITDA, beta; medians; source snapshot kept as memo.
B26: Forecast | C26: FY2026E-FY2030E, one assumption per line, incl. recurring restructuring; UFCF and company-definition FCF conversion.
B27: Comps | C27: Lease-adjusted peer multiples, unlevered betas, franchise-heavy primary set, implied value, 50/50 rationale, growth table.
B28: WACC | C28: Primary bottom-up beta from franchise-heavy peers (0.60), cost of equity and debt, sensitivities, beta reconciliation, MCD unlevered beta.
B29: DCF | C29: Stub from the 30-Jun-2026 balance sheet, mid-year convention, normalised terminal year, guide checks.
B30: Valuation | C30: 60/40 target, rating (exact bands), football field, WACC vs growth grids, beta check, scenarios, reverse DCF, consensus and comps-weighting checks.
B31: Model_Review | C31: Guide review and five feedback rounds: each point, whether it was right, what changed, target bridges.
B32: Reference_Data | C32: Figures from the 2025 10-K and the Q2 2026 release, with page references; feeds Historical_Drivers, Comps and Forecast.

Sheet Valuation
A1: Target price - blended DCF and comps, football field and sensitivities
A2: Blue on yellow = assumption. Sensitivity cells recompute the full DCF (stub, mid-year, normalised terminal year) for each WACC / growth pair.
A4: Item | B4: Value | C4: Unit | H4: Note
A5: DCF value per share | B5: =DCF!B50 -> 248.87212 | C5: $ | H5: DCF tab
A6: Comps value per share | B6: =Comps!D31 -> 248.13575 | C6: $ | H6: Comps tab: franchise-heavy peers (YUM, QSR, DPZ), 50% forward P/E + 50% LTM EV/EBITDA. REVISED (feedback): was the all-peer median ($292.69).
A7: Weight on DCF | B7: 0.6 | C7: % | H7: Your 60/40 split. Consistent with the guide: the DCF is the primary method, comps are the cross-check.
A8: Weight on comps | B8: =1-B7 -> 0.4 | C8: %
A9: Target price (blended) | B9: =B5*B7+B6*B8 -> 248.57757 | C9: $
A10: Current share price | B10: =Market_WACC!B6 -> 237.02 | C10: $ | H10: 24-Sep-2026 official close (Stock Analysis / S&P Global). REVISED (feedback): was a $240.09 intraday print.
A11: Upside / (downside) to target | B11: =B9/B10-1 -> 0.048762 | C11: % | H11: The guide cautions that gaps of ~10-15% are within the margin of error of any valuation.
A12: Dividend yield | B12: =Market_WACC!B17 -> 0.032571091 | C12: %
A13: Expected total return (upside + yield) | B13: =B11+B12 -> 0.081333091 | C13: %
A14: Rating under the report framework | B14: =IF(B13>=B48,"Buy",IF(B13<=B50,"Sell","Hold")) -> Hold | H14: Bands in B48 and B50: Buy >= +10%, Sell <= -10%, Hold in between.
A15: FOOTBALL FIELD ($ per share) - DCF guide Key Rule #10
A16: Methodology | B16: Low | C16: Base | D16: High | H16: Range definition
A17: DCF (WACC +/- 0.5%, g +/- 0.5%) | B17: =MIN(D24:F26) -> 203.20742 | C17: =DCF!B50 -> 248.87212 | D17: =MAX(D24:F26) -> 316.97121 | H17: Inner 3x3 of the DCF sensitivity grid below.
A18: Comps: forward P/E | B18: =Comps!C29 -> 193.29336 | C18: =Comps!D29 -> 223.07439 | D18: =Comps!E29 -> 287.901 | H18: Franchise-heavy peers: min / median / max forward P/E x MCD NTM EPS.
A19: Comps: LTM EV/EBITDA (lease-adjusted) | B19: =Comps!C30 -> 246.34636 | C19: =Comps!D30 -> 273.1971 | D19: =Comps!E30 -> 289.07563 | H19: Franchise-heavy peers: min / median / max LTM EV/EBITDA x MCD LTM EBITDA.
A20: Current share price | B20: =Market_WACC!B6 -> 237.02 | C20: =Market_WACC!B6 -> 237.02 | D20: =Market_WACC!B6 -> 237.02 | H20: 24-Sep-2026 close
A21: DCF VALUE PER SHARE ($) - WACC vs TERMINAL GROWTH
A22: WACC (rows) \ terminal growth (columns) | C22: =DCF!$B$8+(-2)*$B$44 -> 0.015 | D22: =DCF!$B$8+(-1)*$B$44 -> 0.02 | E22: =DCF!$B$8+(0)*$B$44 -> 0.025 | F22: =DCF!$B$8+(1)*$B$44 -> 0.03 | G22: =DCF!$B$8+(2)*$B$44 -> 0.035
B23: =DCF!$B$7+(-2)*$B$43 -> 0.065573866 | C23: =IF($B23<=C$22,"n/a",(SUMPRODUCT(DCF!$D$23:$H$23/(1+$B23)^DCF!$D$25:$H$25)+DCF!$H$20*(1+C$22)*DCF!$B$35/($B23-C$22)/(1+$B23)^DCF!$B$38-DCF!$B$13)/DCF!$B$15) -> 256.27116 | D23: =IF($B23<=D$22,"n/a",(SUMPRODUCT(DCF!$D$23:$H$23/(1+$B23)^DCF!$D$25:$H$25)+DCF!$H$20*(1+D$22)*DCF!$B$35/($B23-D$22)/(1+$B23)^DCF!$B$38-DCF!$B$13)/DCF!$B$15) -> 285.32706 | E23: =IF($B23<=E$22,"n/a",(SUMPRODUCT(DCF!$D$23:$H$23/(1+$B23)^DCF!$D$25:$H$25)+DCF!$H$20*(1+E$22)*DCF!$B$35/($B23-E$22)/(1+$B23)^DCF!$B$38-DCF!$B$13)/DCF!$B$15) -> 321.54419 | F23: =IF($B23<=F$22,"n/a",(SUMPRODUCT(DCF!$D$23:$H$23/(1+$B23)^DCF!$D$25:$H$25)+DCF!$H$20*(1+F$22)*DCF!$B$35/($B23-F$22)/(1+$B23)^DCF!$B$38-DCF!$B$13)/DCF!$B$15) -> 367.94214 | G23: =IF($B23<=G$22,"n/a",(SUMPRODUCT(DCF!$D$23:$H$23/(1+$B23)^DCF!$D$25:$H$25)+DCF!$H$20*(1+G$22)*DCF!$B$35/($B23-G$22)/(1+$B23)^DCF!$B$38-DCF!$B$13)/DCF!$B$15) -> 429.51578
B24: =DCF!$B$7+(-1)*$B$43 -> 0.070573866 | C24: =IF($B24<=C$22,"n/a",(SUMPRODUCT(DCF!$D$23:$H$23/(1+$B24)^DCF!$D$25:$H$25)+DCF!$H$20*(1+C$22)*DCF!$B$35/($B24-C$22)/(1+$B24)^DCF!$B$38-DCF!$B$13)/DCF!$B$15) -> 229.01907 | D24: =IF($B24<=D$22,"n/a",(SUMPRODUCT(DCF!$D$23:$H$23/(1+$B24)^DCF!$D$25:$H$25)+DCF!$H$20*(1+D$22)*DCF!$B$35/($B24-D$22)/(1+$B24)^DCF!$B$38-DCF!$B$13)/DCF!$B$15) -> 252.53951 | E24: =IF($B24<=E$22,"n/a",(SUMPRODUCT(DCF!$D$23:$H$23/(1+$B24)^DCF!$D$25:$H$25)+DCF!$H$20*(1+E$22)*DCF!$B$35/($B24-E$22)/(1+$B24)^DCF!$B$38-DCF!$B$13)/DCF!$B$15) -> 281.2209 | F24: =IF($B24<=F$22,"n/a",(SUMPRODUCT(DCF!$D$23:$H$23/(1+$B24)^DCF!$D$25:$H$25)+DCF!$H$20*(1+F$22)*DCF!$B$35/($B24-F$22)/(1+$B24)^DCF!$B$38-DCF!$B$13)/DCF!$B$15) -> 316.97121 | G24: =IF($B24<=G$22,"n/a",(SUMPRODUCT(DCF!$D$23:$H$23/(1+$B24)^DCF!$D$25:$H$25)+DCF!$H$20*(1+G$22)*DCF!$B$35/($B24-G$22)/(1+$B24)^DCF!$B$38-DCF!$B$13)/DCF!$B$15) -> 362.77113
B25: =DCF!$B$7+(0)*$B$43 -> 0.075573866 | C25: =IF($B25<=C$22,"n/a",(SUMPRODUCT(DCF!$D$23:$H$23/(1+$B25)^DCF!$D$25:$H$25)+DCF!$H$20*(1+C$22)*DCF!$B$35/($B25-C$22)/(1+$B25)^DCF!$B$38-DCF!$B$13)/DCF!$B$15) -> 206.26788 | D25: =IF($B25<=D$22,"n/a",(SUMPRODUCT(DCF!$D$23:$H$23/(1+$B25)^DCF!$D$25:$H$25)+DCF!$H$20*(1+D$22)*DCF!$B$35/($B25-D$22)/(1+$B25)^DCF!$B$38-DCF!$B$13)/DCF!$B$15) -> 225.65344 | E25: =IF($B25<=E$22,"n/a",(SUMPRODUCT(DCF!$D$23:$H$23/(1+$B25)^DCF!$D$25:$H$25)+DCF!$H$20*(1+E$22)*DCF!$B$35/($B25-E$22)/(1+$B25)^DCF!$B$38-DCF!$B$13)/DCF!$B$15) -> 248.87212 | F25: =IF($B25<=F$22,"n/a",(SUMPRODUCT(DCF!$D$23:$H$23/(1+$B25)^DCF!$D$25:$H$25)+DCF!$H$20*(1+F$22)*DCF!$B$35/($B25-F$22)/(1+$B25)^DCF!$B$38-DCF!$B$13)/DCF!$B$15) -> 277.18553 | G25: =IF($B25<=G$22,"n/a",(SUMPRODUCT(DCF!$D$23:$H$23/(1+$B25)^DCF!$D$25:$H$25)+DCF!$H$20*(1+G$22)*DCF!$B$35/($B25-G$22)/(1+$B25)^DCF!$B$38-DCF!$B$13)/DCF!$B$15) -> 312.47719
B26: =DCF!$B$7+(1)*$B$43 -> 0.080573866 | C26: =IF($B26<=C$22,"n/a",(SUMPRODUCT(DCF!$D$23:$H$23/(1+$B26)^DCF!$D$25:$H$25)+DCF!$H$20*(1+C$22)*DCF!$B$35/($B26-C$22)/(1+$B26)^DCF!$B$38-DCF!$B$13)/DCF!$B$15) -> 186.98797 | D26: =IF($B26<=D$22,"n/a",(SUMPRODUCT(DCF!$D$23:$H$23/(1+$B26)^DCF!$D$25:$H$25)+DCF!$H$20*(1+D$22)*DCF!$B$35/($B26-D$22)/(1+$B26)^DCF!$B$38-DCF!$B$13)/DCF!$B$15) -> 203.20742 | E26: =IF($B26<=E$22,"n/a",(SUMPRODUCT(DCF!$D$23:$H$23/(1+$B26)^DCF!$D$25:$H$25)+DCF!$H$20*(1+E$22)*DCF!$B$35/($B26-E$22)/(1+$B26)^DCF!$B$38-DCF!$B$13)/DCF!$B$15) -> 222.34542 | F26: =IF($B26<=F$22,"n/a",(SUMPRODUCT(DCF!$D$23:$H$23/(1+$B26)^DCF!$D$25:$H$25)+DCF!$H$20*(1+F$22)*DCF!$B$35/($B26-F$22)/(1+$B26)^DCF!$B$38-DCF!$B$13)/DCF!$B$15) -> 245.26759 | G26: =IF($B26<=G$22,"n/a",(SUMPRODUCT(DCF!$D$23:$H$23/(1+$B26)^DCF!$D$25:$H$25)+DCF!$H$20*(1+G$22)*DCF!$B$35/($B26-G$22)/(1+$B26)^DCF!$B$38-DCF!$B$13)/DCF!$B$15) -> 273.21942
B27: =DCF!$B$7+(2)*$B$43 -> 0.085573866 | C27: =IF($B27<=C$22,"n/a",(SUMPRODUCT(DCF!$D$23:$H$23/(1+$B27)^DCF!$D$25:$H$25)+DCF!$H$20*(1+C$22)*DCF!$B$35/($B27-C$22)/(1+$B27)^DCF!$B$38-DCF!$B$13)/DCF!$B$15) -> 170.4415 | D27: =IF($B27<=D$22,"n/a",(SUMPRODUCT(DCF!$D$23:$H$23/(1+$B27)^DCF!$D$25:$H$25)+DCF!$H$20*(1+D$22)*DCF!$B$35/($B27-D$22)/(1+$B27)^DCF!$B$38-DCF!$B$13)/DCF!$B$15) -> 184.18577 | E27: =IF($B27<=E$22,"n/a",(SUMPRODUCT(DCF!$D$23:$H$23/(1+$B27)^DCF!$D$25:$H$25)+DCF!$H$20*(1+E$22)*DCF!$B$35/($B27-E$22)/(1+$B27)^DCF!$B$38-DCF!$B$13)/DCF!$B$15) -> 200.19905 | F27: =IF($B27<=F$22,"n/a",(SUMPRODUCT(DCF!$D$23:$H$23/(1+$B27)^DCF!$D$25:$H$25)+DCF!$H$20*(1+F$22)*DCF!$B$35/($B27-F$22)/(1+$B27)^DCF!$B$38-DCF!$B$13)/DCF!$B$15) -> 219.09376 | G27: =IF($B27<=G$22,"n/a",(SUMPRODUCT(DCF!$D$23:$H$23/(1+$B27)^DCF!$D$25:$H$25)+DCF!$H$20*(1+G$22)*DCF!$B$35/($B27-G$22)/(1+$B27)^DCF!$B$38-DCF!$B$13)/DCF!$B$15) -> 241.72454
A29: BLENDED TARGET PRICE ($) - WACC vs TERMINAL GROWTH (comps held constant)
A30: WACC (rows) \ terminal growth (columns) | C30: =DCF!$B$8+(-2)*$B$44 -> 0.015 | D30: =DCF!$B$8+(-1)*$B$44 -> 0.02 | E30: =DCF!$B$8+(0)*$B$44 -> 0.025 | F30: =DCF!$B$8+(1)*$B$44 -> 0.03 | G30: =DCF!$B$8+(2)*$B$44 -> 0.035
B31: =DCF!$B$7+(-2)*$B$43 -> 0.065573866 | C31: =IF($B31<=C$30,"n/a",$B$7*(SUMPRODUCT(DCF!$D$23:$H$23/(1+$B31)^DCF!$D$25:$H$25)+DCF!$H$20*(1+C$30)*DCF!$B$35/($B31-C$30)/(1+$B31)^DCF!$B$38-DCF!$B$13)/DCF!$B$15+$B$8*$B$6) -> 253.017 | D31: =IF($B31<=D$30,"n/a",$B$7*(SUMPRODUCT(DCF!$D$23:$H$23/(1+$B31)^DCF!$D$25:$H$25)+DCF!$H$20*(1+D$30)*DCF!$B$35/($B31-D$30)/(1+$B31)^DCF!$B$38-DCF!$B$13)/DCF!$B$15+$B$8*$B$6) -> 270.45053 | E31: =IF($B31<=E$30,"n/a",$B$7*(SUMPRODUCT(DCF!$D$23:$H$23/(1+$B31)^DCF!$D$25:$H$25)+DCF!$H$20*(1+E$30)*DCF!$B$35/($B31-E$30)/(1+$B31)^DCF!$B$38-DCF!$B$13)/DCF!$B$15+$B$8*$B$6) -> 292.18081 | F31: =IF($B31<=F$30,"n/a",$B$7*(SUMPRODUCT(DCF!$D$23:$H$23/(1+$B31)^DCF!$D$25:$H$25)+DCF!$H$20*(1+F$30)*DCF!$B$35/($B31-F$30)/(1+$B31)^DCF!$B$38-DCF!$B$13)/DCF!$B$15+$B$8*$B$6) -> 320.01958 | G31: =IF($B31<=G$30,"n/a",$B$7*(SUMPRODUCT(DCF!$D$23:$H$23/(1+$B31)^DCF!$D$25:$H$25)+DCF!$H$20*(1+G$30)*DCF!$B$35/($B31-G$30)/(1+$B31)^DCF!$B$38-DCF!$B$13)/DCF!$B$15+$B$8*$B$6) -> 356.96377
B32: =DCF!$B$7+(-1)*$B$43 -> 0.070573866 | C32: =IF($B32<=C$30,"n/a",$B$7*(SUMPRODUCT(DCF!$D$23:$H$23/(1+$B32)^DCF!$D$25:$H$25)+DCF!$H$20*(1+C$30)*DCF!$B$35/($B32-C$30)/(1+$B32)^DCF!$B$38-DCF!$B$13)/DCF!$B$15+$B$8*$B$6) -> 236.66574 | D32: =IF($B32<=D$30,"n/a",$B$7*(SUMPRODUCT(DCF!$D$23:$H$23/(1+$B32)^DCF!$D$25:$H$25)+DCF!$H$20*(1+D$30)*DCF!$B$35/($B32-D$30)/(1+$B32)^DCF!$B$38-DCF!$B$13)/DCF!$B$15+$B$8*$B$6) -> 250.778 | E32: =IF($B32<=E$30,"n/a",$B$7*(SUMPRODUCT(DCF!$D$23:$H$23/(1+$B32)^DCF!$D$25:$H$25)+DCF!$H$20*(1+E$30)*DCF!$B$35/($B32-E$30)/(1+$B32)^DCF!$B$38-DCF!$B$13)/DCF!$B$15+$B$8*$B$6) -> 267.98684 | F32: =IF($B32<=F$30,"n/a",$B$7*(SUMPRODUCT(DCF!$D$23:$H$23/(1+$B32)^DCF!$D$25:$H$25)+DCF!$H$20*(1+F$30)*DCF!$B$35/($B32-F$30)/(1+$B32)^DCF!$B$38-DCF!$B$13)/DCF!$B$15+$B$8*$B$6) -> 289.43703 | G32: =IF($B32<=G$30,"n/a",$B$7*(SUMPRODUCT(DCF!$D$23:$H$23/(1+$B32)^DCF!$D$25:$H$25)+DCF!$H$20*(1+G$30)*DCF!$B$35/($B32-G$30)/(1+$B32)^DCF!$B$38-DCF!$B$13)/DCF!$B$15+$B$8*$B$6) -> 316.91698
B33: =DCF!$B$7+(0)*$B$43 -> 0.075573866 | C33: =IF($B33<=C$30,"n/a",$B$7*(SUMPRODUCT(DCF!$D$23:$H$23/(1+$B33)^DCF!$D$25:$H$25)+DCF!$H$20*(1+C$30)*DCF!$B$35/($B33-C$30)/(1+$B33)^DCF!$B$38-DCF!$B$13)/DCF!$B$15+$B$8*$B$6) -> 223.01503 | D33: =IF($B33<=D$30,"n/a",$B$7*(SUMPRODUCT(DCF!$D$23:$H$23/(1+$B33)^DCF!$D$25:$H$25)+DCF!$H$20*(1+D$30)*DCF!$B$35/($B33-D$30)/(1+$B33)^DCF!$B$38-DCF!$B$13)/DCF!$B$15+$B$8*$B$6) -> 234.64636 | E33: =IF($B33<=E$30,"n/a",$B$7*(SUMPRODUCT(DCF!$D$23:$H$23/(1+$B33)^DCF!$D$25:$H$25)+DCF!$H$20*(1+E$30)*DCF!$B$35/($B33-E$30)/(1+$B33)^DCF!$B$38-DCF!$B$13)/DCF!$B$15+$B$8*$B$6) -> 248.57757 | F33: =IF($B33<=F$30,"n/a",$B$7*(SUMPRODUCT(DCF!$D$23:$H$23/(1+$B33)^DCF!$D$25:$H$25)+DCF!$H$20*(1+F$30)*DCF!$B$35/($B33-F$30)/(1+$B33)^DCF!$B$38-DCF!$B$13)/DCF!$B$15+$B$8*$B$6) -> 265.56562 | G33: =IF($B33<=G$30,"n/a",$B$7*(SUMPRODUCT(DCF!$D$23:$H$23/(1+$B33)^DCF!$D$25:$H$25)+DCF!$H$20*(1+G$30)*DCF!$B$35/($B33-G$30)/(1+$B33)^DCF!$B$38-DCF!$B$13)/DCF!$B$15+$B$8*$B$6) -> 286.74061
B34: =DCF!$B$7+(1)*$B$43 -> 0.080573866 | C34: =IF($B34<=C$30,"n/a",$B$7*(SUMPRODUCT(DCF!$D$23:$H$23/(1+$B34)^DCF!$D$25:$H$25)+DCF!$H$20*(1+C$30)*DCF!$B$35/($B34-C$30)/(1+$B34)^DCF!$B$38-DCF!$B$13)/DCF!$B$15+$B$8*$B$6) -> 211.44708 | D34: =IF($B34<=D$30,"n/a",$B$7*(SUMPRODUCT(DCF!$D$23:$H$23/(1+$B34)^DCF!$D$25:$H$25)+DCF!$H$20*(1+D$30)*DCF!$B$35/($B34-D$30)/(1+$B34)^DCF!$B$38-DCF!$B$13)/DCF!$B$15+$B$8*$B$6) -> 221.17875 | E34: =IF($B34<=E$30,"n/a",$B$7*(SUMPRODUCT(DCF!$D$23:$H$23/(1+$B34)^DCF!$D$25:$H$25)+DCF!$H$20*(1+E$30)*DCF!$B$35/($B34-E$30)/(1+$B34)^DCF!$B$38-DCF!$B$13)/DCF!$B$15+$B$8*$B$6) -> 232.66155 | F34: =IF($B34<=F$30,"n/a",$B$7*(SUMPRODUCT(DCF!$D$23:$H$23/(1+$B34)^DCF!$D$25:$H$25)+DCF!$H$20*(1+F$30)*DCF!$B$35/($B34-F$30)/(1+$B34)^DCF!$B$38-DCF!$B$13)/DCF!$B$15+$B$8*$B$6) -> 246.41485 | G34: =IF($B34<=G$30,"n/a",$B$7*(SUMPRODUCT(DCF!$D$23:$H$23/(1+$B34)^DCF!$D$25:$H$25)+DCF!$H$20*(1+G$30)*DCF!$B$35/($B34-G$30)/(1+$B34)^DCF!$B$38-DCF!$B$13)/DCF!$B$15+$B$8*$B$6) -> 263.18595
B35: =DCF!$B$7+(2)*$B$43 -> 0.085573866 | C35: =IF($B35<=C$30,"n/a",$B$7*(SUMPRODUCT(DCF!$D$23:$H$23/(1+$B35)^DCF!$D$25:$H$25)+DCF!$H$20*(1+C$30)*DCF!$B$35/($B35-C$30)/(1+$B35)^DCF!$B$38-DCF!$B$13)/DCF!$B$15+$B$8*$B$6) -> 201.5192 | D35: =IF($B35<=D$30,"n/a",$B$7*(SUMPRODUCT(DCF!$D$23:$H$23/(1+$B35)^DCF!$D$25:$H$25)+DCF!$H$20*(1+D$30)*DCF!$B$35/($B35-D$30)/(1+$B35)^DCF!$B$38-DCF!$B$13)/DCF!$B$15+$B$8*$B$6) -> 209.76576 | E35: =IF($B35<=E$30,"n/a",$B$7*(SUMPRODUCT(DCF!$D$23:$H$23/(1+$B35)^DCF!$D$25:$H$25)+DCF!$H$20*(1+E$30)*DCF!$B$35/($B35-E$30)/(1+$B35)^DCF!$B$38-DCF!$B$13)/DCF!$B$15+$B$8*$B$6) -> 219.37373 | F35: =IF($B35<=F$30,"n/a",$B$7*(SUMPRODUCT(DCF!$D$23:$H$23/(1+$B35)^DCF!$D$25:$H$25)+DCF!$H$20*(1+F$30)*DCF!$B$35/($B35-F$30)/(1+$B35)^DCF!$B$38-DCF!$B$13)/DCF!$B$15+$B$8*$B$6) -> 230.71056 | G35: =IF($B35<=G$30,"n/a",$B$7*(SUMPRODUCT(DCF!$D$23:$H$23/(1+$B35)^DCF!$D$25:$H$25)+DCF!$H$20*(1+G$30)*DCF!$B$35/($B35-G$30)/(1+$B35)^DCF!$B$38-DCF!$B$13)/DCF!$B$15+$B$8*$B$6) -> 244.28902
A42: SENSITIVITY SETTINGS & CHECKS
A43: WACC step | B43: 0.005 | C43: % | H43: Base WACC +/- 2 steps (about 6.5-8.5%): covers the beta sensitivities on WACC rows 54-64.
A44: Terminal growth step | B44: 0.005 | C44: % | H44: Base g +/- 2 steps (1.5%-3.5%).
A45: Check: DCF grid centre - DCF value (should be 0) | B45: =E25-B5 -> 0 | C45: $
A46: Check: blended grid centre - target (should be 0) | B46: =E33-B9 -> 0 | C46: $
A48: Rating band: 'Buy' at or above total return of | B48: 0.1 | C48: % | H48: REVISED 26-Sep (round 4): exact bands. Buy >= +10%; Hold > -10% and < +10%; Sell <= -10% (12-month total return including dividends). Replaces "Buy above +10 to 15%".
A50: Rating band: 'Sell' at or below total return of | B50: -0.1 | C50: %
...

Sheet DCF
A1: Discounted cash flow - intrinsic value per share
A2: Unlevered FCF from Forecast. Stub period from the latest balance sheet (30-Jun-2026), mid-year convention, normalised terminal year. Orange = changed after the review.
A4: INPUTS
A5: Valuation date | B5: =Market_WACC!B7 -> 46289 | J5: Price date
A6: Balance sheet date (latest 10-Q) | B6: =DATE(2026,6,30) -> 46203 | J6: NEW: net debt from the Q2-2026 10-Q instead of FY25 year-end (multiples guide Key Rule #15: update the bridge to the latest interim balance sheet).
A7: WACC | B7: =WACC!B39 -> 0.075573866 | C7: % | J7: WACC tab B39: primary bottom-up beta from franchise-heavy peers (revised 26-Sep).
A8: Terminal growth rate | B8: 0.025 | C8: % | J8: REVISED from 3.0%: guide says 1-3% for developed markets, "perhaps in line with inflation" and below GDP growth (DCF guide Key Rule #6). 3.0% sat at the ceiling; 2.5% is the midpoint of the plausible range.
A9: Mid-year convention (1 = on, 0 = year-end) | B9: 1 | J9: NEW: cash arrives through the year, so mid-year discounting is more accurate (DCF guide Key Rule #11). Stub handled as the guide describes.
A10: Cash & equivalents (30-Jun-2026) | B10: 822 | C10: $mm | J10: MCD 10-Q Q2-2026 balance sheet.
A11: Long-term debt, carrying (30-Jun-2026) | B11: 39863 | C11: $mm | J11: MCD 10-Q Q2-2026 balance sheet.
A12: Debt at fair value (30-Jun-2026) | B12: 38300 | C12: $mm | J12: MCD 10-Q Q2-2026 fair value note: $38.3bn (quoted prices, Level 2).
A13: Net debt used in bridge (fair-value debt - cash) | B13: =B12-B10 -> 37478 | C13: $mm | J13: Market value of debt per multiples guide Key Rule #10. Book-value alternative: $39,041m (-$2.2/share).
A14: Memo: operating lease liabilities (not deducted) | B14: =690+14039 -> 14729 | C14: $mm | J14: 10-Q: current $690m + long-term $14,039m. Not deducted because rent is already inside FCF (no double counting).
A15: Diluted shares | B15: =WACC!B11 -> 709.64 | C15: mm | J15: WACC tab
A16: Current share price | B16: =Market_WACC!B6 -> 237.02 | C16: $ | J16: Market_WACC
A18: Free cash flow | B18: Unit | D18: FY2026E | E18: FY2027E | F18: FY2028E | G18: FY2029E | H18: FY2030E | I18: Terminal (FY31 norm.) | J18: Note
A19: Fiscal year end | D19: =DATE(2026,12,31) -> 46387 | E19: =DATE(2027,12,31) -> 46752 | F19: =DATE(2028,12,31) -> 47118 | G19: =DATE(2029,12,31) -> 47483 | H19: =DATE(2030,12,31) -> 47848
A20: Revenue | C20: $mm | D20: =Forecast!D21 -> 28363.675 | E20: =Forecast!E21 -> 28221.857 | F20: =Forecast!F21 -> 28165.413 | G20: =Forecast!G21 -> 29348.36 | H20: =Forecast!H21 -> 30580.991 | I20: =H20*(1+B8) -> 31345.516
A21: Unlevered free cash flow | C21: $mm | D21: =Forecast!D43 -> 8445.3079 | E21: =Forecast!E43 -> 9456.8762 | F21: =Forecast!F43 -> 10004.618 | G21: =Forecast!G43 -> 10798.629 | H21: =Forecast!H43 -> 11516.337 | I21: =I20*B35 -> 11617.393 | J21: Forecast row 43.
A22: Share of year after balance-sheet date | C22: % | D22: =MAX(0,MIN(1,(D19-$B$6)/365)) -> 0.50410959 | E22: =MAX(0,MIN(1,(E19-$B$6)/365)) -> 1 | F22: =MAX(0,MIN(1,(F19-$B$6)/365)) -> 1 | G22: =MAX(0,MIN(1,(G19-$B$6)/365)) -> 1 | H22: =MAX(0,MIN(1,(H19-$B$6)/365)) -> 1 | J22: FY26: only H2 cash flow is counted, because H1 cash is already reflected in the 30-Jun net debt (DCF guide Key Rule #11, stub periods).
A23: FCF counted | C23: $mm | D23: =D21*D22 -> 4257.3607 | E23: =E21*E22 -> 9456.8762 | F23: =F21*F22 -> 10004.618 | G23: =G21*G22 -> 10798.629 | H23: =H21*H22 -> 11516.337
A24: Cash-flow timing date | D24: =IF($B$9=1,D19-(D19-MAX($B$6,D19-365))/2,D19) -> 46295 | E24: =IF($B$9=1,E19-(E19-MAX($B$6,E19-365))/2,E19) -> 46569.5 | F24: =IF($B$9=1,F19-(F19-MAX($B$6,F19-365))/2,F19) -> 46935.5 | G24: =IF($B$9=1,G19-(G19-MAX($B$6,G19-365))/2,G19) -> 47300.5 | H24: =IF($B$9=1,H19-(H19-MAX($B$6,H19-365))/2,H19) -> 47665.5 | J24: Mid-year: midpoint of the period counted (30-Sep for the FY26 stub, ~1-Jul after). Year-end if the switch is 0.
A25: Discount period (years from valuation date) | C25: yrs | D25: =MAX(0,(D24-$B$5)/365) -> 0.016438356 | E25: =MAX(0,(E24-$B$5)/365) -> 0.76849315 | F25: =MAX(0,(F24-$B$5)/365) -> 1.7712329 | G25: =MAX(0,(G24-$B$5)/365) -> 2.7712329 | H25: =MAX(0,(H24-$B$5)/365) -> 3.7712329
A26: Discount factor | D26: =1/(1+$B$7)^D25 -> 0.99880311 | E26: =1/(1+$B$7)^E25 -> 0.94555042 | F26: =1/(1+$B$7)^F25 -> 0.87893704 | G26: =1/(1+$B$7)^G25 -> 0.81717961 | H26: =1/(1+$B$7)^H25 -> 0.7597615
A27: PV of FCF | C27: $mm | D27: =D23*D26 -> 4252.2651 | E27: =E23*E26 -> 8941.9533 | F27: =F23*F26 -> 8793.4291 | G27: =G23*G26 -> 8824.4194 | H27: =H23*H26 -> 8749.6696
A29: NORMALISED TERMINAL YEAR & TERMINAL VALUE
A30: Operating margin held at FY2030 level | B30: =Forecast!H10 -> 0.53 | C30: % | J30: Margin expansion stops at the 2030 target.
A31: Tax rate | B31: =Forecast!H14 -> 0.22 | C31: %
A32: D&A % of revenue | B32: =Forecast!H11 -> 0.086 | C32: %
A33: Capex % of revenue (normalised) | B33: =AVERAGE(Forecast!E45:H45) -> 0.11877623 | C33: % | J33: NEW: FY27-30 average instead of the falling FY30 ratio. Flat $3.45bn capex makes FY30 capex % unusually low, and NEXT partnering runs to 2036 (DCF guide Key Rule #11, normalised terminal year).
A34: Working capital & other % of revenue | B34: =Forecast!H13 -> -0.01 | C34: %
A35: Normalised UFCF margin | B35: =B30*(1-B31)+B32-B33+B34 -> 0.37062377 | C35: % | J35: Terminal-year UFCF = FY31 revenue x this margin.
A36: Terminal-year UFCF vs FY2030 UFCF | B36: =I21/H21-1 -> 0.0087750208 | C36: % | J36: Growth into the terminal year after normalising capex.
A37: Terminal value at end-FY2030 | B37: =IF(B7>B8,I21/(B7-B8),"") -> 229711.39 | C37: $mm | J37: Perpetuity growth: terminal-year UFCF / (WACC - g).
A38: Terminal-value discount period | B38: =(H19-B5)/365-IF(B9=1,0.5,0) -> 3.7712329 | C38: yrs | J38: Half a year earlier under the mid-year convention with the perpetuity method (DCF guide Key Rule #11).
A39: PV of terminal value | B39: =IF(B37="","",B37/(1+B7)^B38) -> 174525.87 | C39: $mm
A40: Implied exit EV/EBITDA (TV / FY2030E EBITDA) | B40: =IF(B37="","",B37/Forecast!H25) -> 12.194114 | C40: x | J40: Cross-check vs lease-adjusted peer median and MCD today (checks below).
A42: ENTERPRISE VALUE TO VALUE PER SHARE
A43: Sum of PV of FCF (H2-FY26 to FY30) | B43: =SUM(D27:H27) -> 39561.736 | C43: $mm
A44: PV of terminal value | B44: =B39 -> 174525.87 | C44: $mm
...

Sheet Forecast
A1: Five-year forecast (FY2026E-FY2030E)
A2: Blue on yellow = assumption (one per line). Black = formula. Green = link. Orange fill = changed after the review against the valuation guides (see Model_Review). $ millions unless stated.
A4: Line item | B4: Unit | C4: FY2025A | D4: FY2026E | E4: FY2027E | F4: FY2028E | G4: FY2029E | H4: FY2030E | I4: Source / rationale
A5: A. ASSUMPTIONS (one per line)
A6: Comparable sales growth | B6: % | D6: 0.02 | E6: 0.025 | F6: 0.03 | G6: 0.03 | H6: 0.03 | I6: H1-26 comps +2.5%, Q2 +1.3%, U.S. July slightly negative; IOM/IDL expected to accelerate in Q3 -> ~2% FY26. U.S. recovery "a 2027 story" (Q2 call); Investor Day share-gain targets with flat industry traffic -> 3% steady state.
A7: New-restaurant contribution to revenue growth | B7: % | D7: 0.015 | E7: 0.015 | F7: 0.013 | G7: 0.012 | H7: 0.012 | I7: Investor Day: new units add ~2.5% to systemwide sales 2026-27, easing to ~2% by 2030. Cut ~40% for revenue because most openings are IDL (royalty ~5% vs ~14-17% take in U.S./IOM).
A8: FX translation impact on revenue | B8: % | D8: 0.025 | E8: 0 | F8: 0 | G8: 0 | H8: 0 | I8: H1-26 revenue +6.4% reported vs +3% cc (Q2 release p.2). No FX assumed after FY26.
A9: Refranchising impact on revenue | B9: % | D9: -0.005 | E9: -0.045 | F9: -0.045 | G9: 0 | H9: 0 | I9: Investor Day: franchised mix ~95% -> ~98% by end-2028 (2,012 company units at 30-Jun-26, 10-Q). Swaps company sales for ~15% rent/royalty: lowers revenue, broadly neutral to operating income, lifts margin %.
A10: Operating margin (adjusted, before restructuring) | B10: % | D10: 0.47 | E10: 0.495 | F10: 0.515 | G10: 0.525 | H10: 0.53 | I10: REVISED: ramp smoothed so the final-year step is 0.5pp (was 0.7pp) - DCF guide Key Rule #4: margins should stabilise by the end of the forecast. FY25 adj. 46.9%; Investor Day target low-to-mid 50s by 2030; 53% = low end.
A11: D&A as % of revenue | B11: % | D11: 0.082 | E11: 0.084 | F11: 0.086 | G11: 0.086 | H11: 0.086 | I11: FY25 8.2%. H1-26 D&A $1,131m (10-Q cash flow) ~ 8.3% of H1 revenue. Drifts up as capex rises and refranchising shrinks revenue.
A12: Capital expenditures | B12: $mm | D12: 3800 | E12: 3450 | F12: 3450 | G12: 3450 | H12: 3450 | I12: FY26 guide $3.7-3.9bn (H1 actual $1,516m). Investor Day: ~$3.0bn baseline p.a. 2027-30 + $1.5-2.0bn cumulative NEXT capital partnering.
A13: Change in working capital & other operating items | B13: % rev | D13: -0.01 | E13: -0.01 | F13: -0.01 | G13: -0.01 | H13: -0.01 | I13: REVISED LABEL: stock-based compensation is NOT added back (DCF guide Key Rule #2 - SBC is a real cost); it stays expensed inside operating income. CFO - NI - D&A ran -3.3% / -3.4% / -0.8% of revenue FY23-25.
A14: Tax rate | B14: % | D14: 0.22 | E14: 0.22 | F14: 0.22 | G14: 0.22 | H14: 0.22 | I14: FY26 guidance 21-23% -> 22%. Applied to operating income with no interest tax shield (DCF guide Key Rule #4).
A15: Interest expense growth | B15: % | D15: 0.05 | E15: 0.04 | F15: 0.04 | G15: 0.03 | H15: 0.03 | I15: FY26 guide +4-6%. EPS only (DCF is unlevered).
A16: Diluted share count change (buybacks) | B16: % | D16: -0.008 | E16: -0.008 | F16: -0.008 | G16: -0.008 | H16: -0.008 | I16: EPS only. FY21-25 diluted shares -1.2% p.a.
A17: Restructuring & special charges (pre-tax, cash) | B17: $mm | D17: 250 | E17: 100 | F17: 0 | G17: 0 | H17: 0 | I17: NEW: charges recurred every year 2023-26 ($795m cumulative), so they are not "non-recurring" (DCF guide Key Rule #8) and must reduce cash flow. 10-Q Q2-26: ~$250m expected in 2026, programme completes during 2027.
A19: B. INCOME STATEMENT (adjusted basis, for EPS and multiples)
A20: Revenue growth | B20: % | C20: =Historical_5Y!G12 -> 0.037229938 | D20: =SUM(D6:D9) -> 0.055 | E20: =SUM(E6:E9) -> -0.005 | F20: =SUM(F6:F9) -> -0.002 | G20: =SUM(G6:G9) -> 0.042 | H20: =SUM(H6:H9) -> 0.042 | I20: Comps + new units + FX + refranchising (rows 6-9).
A21: Total revenues | B21: $mm | C21: =Historical_5Y!G9 -> 26885 | D21: =C21*(1+D20) -> 28363.675 | E21: =D21*(1+E20) -> 28221.857 | F21: =E21*(1+F20) -> 28165.413 | G21: =F21*(1+G20) -> 29348.36 | H21: =G21*(1+H20) -> 30580.991
A22: Operating income (adjusted) | B22: $mm | C22: =Historical_5Y!G16 -> 12621 | D22: =D21*D10 -> 13330.927 | E22: =E21*E10 -> 13969.819 | F22: =F21*F10 -> 14505.188 | G22: =G21*G10 -> 15407.889 | H22: =H21*H10 -> 16207.925 | I22: FY25A non-GAAP (excl. $229m restructuring).
A23: Operating margin (adjusted) | B23: % | C23: =C22/C21 -> 0.46944393 | D23: =D22/D21 -> 0.47 | E23: =E22/E21 -> 0.495 | F23: =F22/F21 -> 0.515 | G23: =G22/G21 -> 0.525 | H23: =H22/H21 -> 0.53
A24: Depreciation & amortization | B24: $mm | C24: =Historical_5Y!G22 -> 2199 | D24: =D21*D11 -> 2325.8214 | E24: =E21*E11 -> 2370.636 | F24: =F21*F11 -> 2422.2255 | G24: =G21*G11 -> 2523.959 | H24: =H21*H11 -> 2629.9653 | I24: Cash-flow-statement D&A (the all-inclusive figure - multiples guide Key Rule #4).
A25: EBITDA (adjusted) | B25: $mm | C25: =C22+C24 -> 14820 | D25: =D22+D24 -> 15656.749 | E25: =E22+E24 -> 16340.455 | F25: =F22+F24 -> 16927.413 | G25: =G22+G24 -> 17931.848 | H25: =H22+H24 -> 18837.891
A26: Interest expense | B26: $mm | C26: =Reference_Data!E22 -> 1582 | D26: =C26*(1+D15) -> 1661.1 | E26: =D26*(1+E15) -> 1727.544 | F26: =E26*(1+F15) -> 1796.6458 | G26: =F26*(1+G15) -> 1850.5451 | H26: =G26*(1+H15) -> 1906.0615 | I26: FY25A 10-K p.39.
A27: Pre-tax income (adjusted) | B27: $mm | D27: =D22-D26 -> 11669.827 | E27: =E22-E26 -> 12242.275 | F27: =F22-F26 -> 12708.542 | G27: =G22-G26 -> 13557.344 | H27: =H22-H26 -> 14301.864
A28: Income taxes | B28: $mm | D28: =D27*D14 -> 2567.362 | E28: =E27*E14 -> 2693.3005 | F28: =F27*F14 -> 2795.8792 | G28: =G27*G14 -> 2982.6157 | H28: =H27*H14 -> 3146.4101
A29: Net income (adjusted) | B29: $mm | C29: =C31*C30 -> 8740.08 | D29: =D27-D28 -> 9102.4653 | E29: =E27-E28 -> 9548.9745 | F29: =F27-F28 -> 9912.6627 | G29: =G27-G28 -> 10574.728 | H29: =H27-H28 -> 11155.454
A30: Weighted avg diluted shares | B30: mm | C30: =Historical_5Y!G26 -> 716.4 | D30: =C30*(1+D16) -> 710.6688 | E30: =D30*(1+E16) -> 704.98345 | F30: =E30*(1+F16) -> 699.34358 | G30: =F30*(1+G16) -> 693.74883 | H30: =G30*(1+H16) -> 688.19884
A31: Diluted EPS (adjusted) | B31: $/sh | C31: =Historical_5Y!G20 -> 12.2 | D31: =D29/D30 -> 12.808309 | E31: =E29/E30 -> 13.544963 | F31: =F29/F30 -> 14.174238 | G31: =G29/G30 -> 15.242877 | H31: =H29/H30 -> 16.209638 | I31: Adjusted basis kept for P/E because peer forward P/Es are built on consensus (adjusted) EPS. FY26E check: H1-26 adj. $6.21 (release p.3) + H2-25 $6.34 x ~1.05 = ~$12.9.
A32: EPS growth | B32: % | D32: =D31/C31-1 -> 0.049861355 | E32: =E31/D31-1 -> 0.057513774 | F32: =F31/E31-1 -> 0.046458285 | G32: =G31/F31-1 -> 0.075393034 | H32: =H31/G31-1 -> 0.063423747
A34: C. UNLEVERED FREE CASH FLOW (feeds the DCF)
A35: Operating income (adjusted) | B35: $mm | D35: =D22 -> 13330.927 | E35: =E22 -> 13969.819 | F35: =F22 -> 14505.188 | G35: =G22 -> 15407.889 | H35: =H22 -> 16207.925
A36: Less: restructuring & special charges | B36: $mm | D36: =-D17 -> -250 | E36: =-E17 -> -100 | F36: =-F17 -> 0 | G36: =-G17 -> 0 | H36: =-H17 -> 0 | I36: Cash cost; tax-deductible, so it also lowers taxes below.
A37: EBIT used in DCF | B37: $mm | D37: =D35+D36 -> 13080.927 | E37: =E35+E36 -> 13869.819 | F37: =F35+F36 -> 14505.188 | G37: =G35+G36 -> 15407.889 | H37: =H35+H36 -> 16207.925
A38: Less: taxes on EBIT | B38: $mm | D38: =-D37*D14 -> -2877.804 | E38: =-E37*E14 -> -3051.3602 | F38: =-F37*F14 -> -3191.1413 | G38: =-G37*G14 -> -3389.7356 | H38: =-H37*H14 -> -3565.7436 | I38: EBIT x tax rate - no interest tax shield (it sits in the WACC).
A39: NOPAT | B39: $mm | D39: =D37+D38 -> 10203.123 | E39: =E37+E38 -> 10818.459 | F39: =F37+F38 -> 11314.046 | G39: =G37+G38 -> 12018.154 | H39: =H37+H38 -> 12642.182
A40: Plus: D&A | B40: $mm | D40: =D24 -> 2325.8214 | E40: =E24 -> 2370.636 | F40: =F24 -> 2422.2255 | G40: =G24 -> 2523.959 | H40: =H24 -> 2629.9653
A41: Less: capital expenditures | B41: $mm | C41: =-Historical_5Y!G32 -> -3365 | D41: =-D12 -> -3800 | E41: =-E12 -> -3450 | F41: =-F12 -> -3450 | G41: =-G12 -> -3450 | H41: =-H12 -> -3450
A42: Plus/(less): working capital & other items | B42: $mm | D42: =D21*D13 -> -283.63675 | E42: =E21*E13 -> -282.21857 | F42: =F21*F13 -> -281.65413 | G42: =G21*G13 -> -293.4836 | H42: =H21*H13 -> -305.80991
A43: Unlevered free cash flow (UFCF) - DCF basis, before interest | B43: $mm | D43: =SUM(D39:D42) -> 8445.3079 | E43: =SUM(E39:E42) -> 9456.8762 | F43: =SUM(F39:F42) -> 10004.618 | G43: =SUM(G39:G42) -> 10798.629 | H43: =SUM(H39:H42) -> 11516.337 | I43: UFCF = NOPAT + D&A - capex - working capital, after restructuring cash costs and before interest; it feeds the DCF. NOT comparable with the company "free cash flow" (row 46). Rent on leases stays in operating costs, so lease liabilities are not deducted in the bridge (DCF guide Key Rules #6, #13).
...

Sheet Market_WACC
A1: Market data & WACC inputs
A2: Blue = market data at the official 24-Sep-2026 close. Black = formula. Lavender label = changed after the 25-26 Sep reviews (see Model_Review).
A4: Item | B4: Value | C4: Unit | D4: Source / note
A5: MCD MARKET DATA
A6: Share price | B6: 237.02 | C6: $ | D6: REVISED (feedback): official close 24-Sep-2026 (open $239.70, range $237.02-$242.56, -0.55%). Stock Analysis history page (S&P Global Market Intelligence data), stockanalysis.com/stocks/mcd/history, accessed 25-Sep-2026. Previous version used a 9:56am intraday print of $240.09.
A7: Price date | B7: 46289
A8: Shares outstanding | B8: 707.64 | C8: mm | D8: Stock Analysis (S&P Global Market Intelligence data), stockanalysis.com/stocks/mcd/statistics, 24-Sep-2026
A9: Market cap (price x shares) | B9: =B6*B8 -> 167724.83 | C9: $mm | D9: Formula. The source showed $169.90bn at the 9:56am intraday price.
A10: Beta (5-year, monthly) | B10: 0.41 | D10: Stock Analysis (S&P Global Market Intelligence data), stockanalysis.com/stocks/mcd/statistics, 24-Sep-2026. Low beta = defensive stock; betas differ by provider and window, so check Yahoo/Koyfin too.
A11: 10-year US Treasury yield | B11: 0.0518 | C11: % | D11: REVISED 26-Sep (round 4): 10-year Treasury constant maturity at the 24-Sep-2026 close, 5.18% (FRED DGS10 / Fed H.15, from Treasury's par curve), so every market input shares the price date. Was 5.10% (23-Sep; Treasury par curve 5.11%).
A12: Intraday price when source multiples were captured | B12: 240.09 | C12: $ | D12: Stock Analysis statistics page, 24-Sep-2026 9:56am ET. Rows 14-16 were captured at this price; MCD multiples at the close are rescaled on Peers row 13 and computed on Comps D36:D37.
A13: SOURCE MULTIPLES AS CAPTURED AT THE INTRADAY PRICE (cross-check only, not used in the valuation)
A14: P/E (trailing 12 months) | B14: 19.36 | C14: x | D14: Stock Analysis (S&P Global Market Intelligence data), stockanalysis.com/stocks/mcd/statistics, 24-Sep-2026
A15: P/E (forward) | B15: 18.03 | C15: x | D15: Stock Analysis (S&P Global Market Intelligence data), stockanalysis.com/stocks/mcd/statistics, 24-Sep-2026
A16: EV / EBITDA (trailing) | B16: 14.9 | C16: x | D16: Stock Analysis (S&P Global Market Intelligence data), stockanalysis.com/stocks/mcd/statistics, 24-Sep-2026 (source EV includes leases)
A17: Dividend yield (forward dividend / close) | B17: =B18/B6 -> 0.032571091 | C17: % | D17: REVISED (feedback): formula instead of the source yield (3.22% at the intraday price).
A18: Annual dividend per share (forward) | B18: 7.72 | C18: $ | D18: Stock Analysis statistics, 24-Sep-2026: $7.72 annualised (4 x $1.93).
A19: WACC: see the WACC tab (7.56%, bottom-up beta from franchise-heavy peers). The Step-2 starter WACC that stood here was removed in v6.
A30: ENTERPRISE VALUE (own calculation, FY25 balance sheet)
A31: EV excl. leases (mkt cap + net debt) | B31: =B9+Historical_5Y!G46 -> 206923.83 | C31: $mm | D31: Formula
A32: EV incl. leases | B32: =B9+Historical_5Y!G48 -> 221764.83 | C32: $mm | D32: Formula; closer to data-provider EV definitions
A33: EV (excl. leases) / FY25 EBITDA | B33: =B31/Historical_5Y!G23 -> 14.180635 | C33: x | D33: Formula
A34: P/E on FY25 non-GAAP EPS | B34: =B6/Historical_5Y!G20 -> 19.427869 | C34: x | D34: Formula

Sheet WACC
A1: WACC - primary: bottom-up beta from franchise-heavy peers; other beta methods shown as sensitivities
A2: Blue on yellow = assumption. Green = link. Lavender = changed after the 25-26 Sep reviews. Round 3 (26-Sep beta note): base beta = mean unlevered beta of YUM, QSR, DPZ relevered to MCD (rows 44-50); the three earlier methods are now cross-checks.
A4: Item | B4: Value | C4: Unit | D4: Source / note
A5: MARKET INPUTS & CAPITAL STRUCTURE
A6: Risk-free rate (10-year U.S. Treasury) | B6: =Market_WACC!B11 -> 0.0518 | C6: % | D6: Market_WACC B11 (5.18%, 24-Sep-2026 close).
A7: Raw beta (5-year monthly) | B7: =Market_WACC!B10 -> 0.41 | D7: Market_WACC
A8: Share price | B8: =Market_WACC!B6 -> 237.02 | C8: $ | D8: Market_WACC, 24-Sep-2026
A9: Basic shares outstanding | B9: =Market_WACC!B8 -> 707.64 | C9: mm | D9: 707,641,531 at 30-Jun-2026 (10-Q cover).
A10: Dilutive securities (treasury stock method) | B10: 2 | C10: mm | D10: NEW: MCD 10-Q Q2-2026 - TSM dilution of 2.0m shares for the quarter. Multiples guide Key Rule #2: value per share uses diluted shares.
A11: Diluted shares outstanding | B11: =B9+B10 -> 709.64 | C11: mm | D11: Used in DCF, comps and the equity weight.
A12: Market value of equity (diluted) | B12: =B8*B11 -> 168198.87 | C12: $mm
A13: Market value of debt (fair value, 30-Jun-2026) | B13: =DCF!B12 -> 38300 | C13: $mm | D13: REVISED: 10-Q fair value $38.3bn vs carrying $39.9bn (multiples guide Key Rule #10 - use market values). Leases excluded, as rent is in the FCF.
A14: Tax rate | B14: =Forecast!D14 -> 0.22 | C14: % | D14: Forecast
A15: MCD debt / equity (market) | B15: =B13/B12 -> 0.22770664
A17: COST OF EQUITY (CAPM) - earlier three methods, now cross-checks (primary method in rows 44-50)
A18: Equity risk premium | B18: 0.05 | C18: % | D18: ASSUMPTION: 5.0%, inside the 4-6% range the guide cites (it used 5.5% in its example).
A19: Blume weight on raw beta | B19: 0.67 | D19: Standard Blume adjustment: 0.67 x raw + 0.33.
A20: Method 1 beta: historical (Blume-adjusted) | B20: =B19*B7+(1-B19) -> 0.6047 | D20: Guide method 3 ("easy method"): company's own historical beta.
A21: Peer median unlevered beta | B21: =Comps!M11 -> 0.68894443 | D21: Comps tab: each peer beta / (1 + D/E x (1 - t)), D/E excluding operating leases.
A22: Method 2 beta: peers re-levered at MCD current D/E | B22: =B21*(1+B15*(1-B14)) -> 0.81130866 | D22: Guide method 1.
A23: Peer median debt / total capital | B23: =Comps!O11 -> 0.2362234 | C23: % | D23: Proxy for a "target" capital structure (guide method 2).
A24: Method 3 beta: peers re-levered at peer-median structure | B24: =B21*(1+B23/(1-B23)*(1-B14)) -> 0.8551461 | D24: Guide method 2.
A25: Cost of equity - method 1 | B25: =B6+B20*B18 -> 0.082035 | C25: %
A26: Cost of equity - method 2 | B26: =B6+B22*B18 -> 0.092365433 | C26: %
A27: Cost of equity - method 3 | B27: =B6+B24*B18 -> 0.094557305 | C27: %
A29: COST OF DEBT
A30: Credit spread over 10-year Treasury | B30: 0.009 | C30: % | D30: ASSUMPTION: ~90bp for BBB+/Baa1 long bonds (guide: risk-free + default spread). Check: fair value below carrying implies market yields above coupons.
A31: Pre-tax cost of debt | B31: =B6+B30 -> 0.0608 | C31: %
A32: After-tax cost of debt | B32: =B31*(1-B14) -> 0.047424 | C32: %
A34: WACC - earlier methods (cross-checks) and the WACC used
A35: Equity weight - current market structure | B35: =B12/(B12+B13) -> 0.81452683 | C35: %
A36: WACC - method 1 (historical beta, current structure) | B36: =B35*B25+(1-B35)*B32 -> 0.075615588 | C36: %
A37: WACC - method 2 (peer beta, current structure) | B37: =B35*B26+(1-B35)*B32 -> 0.084030003 | C37: %
A38: WACC - method 3 (peer beta, peer-median structure) | B38: =(1-B23)*B27+B23*B32 -> 0.083423315 | C38: %
A39: WACC used (primary: franchise-heavy bottom-up beta, row 50) | B39: =B50 -> 0.075573866 | C39: % | D39: REVISED 26-Sep (beta note): was the equal-weight average of methods 1-3 (8.03%), which had no economic basis. Now the WACC from the bottom-up franchise-heavy beta; all other estimates are sensitivities (rows 52-64).
A40: Memo: range of the three earlier methods (low / high) | B40: =MIN(B36:B38) -> 0.075615588 | C40: =MAX(B36:B38) -> 0.084030003 | D40: Low in column B, high in column C.
A41: Memo: franchise-heavy MEDIAN beta relevered, WACC (= low case, row 54) | B41: =B35*(B6+Comps!M14*(1+B15*(1-B14))*B18)+(1-B35)*B32 -> 0.07223959 | C41: % | D41: Shows how much SBUX/CMG (company-operated, higher beta) lift the peer beta.
A42: Memo: book equity 30-Jun-2026 (not used) | B42: -1023 | C42: $mm | D42: 10-Q: negative after decades of buybacks, so book weights are meaningless.
A44: PRIMARY BETA - BOTTOM-UP FROM FRANCHISE-HEAVY PEERS (>= 90% of restaurants franchised: YUM, QSR, DPZ)
A45: Mean unlevered beta, franchise-heavy peers | B45: =AVERAGE(Comps!M6,Comps!M7,Comps!M10) -> 0.51262722 | D45: Each peer's 5Y monthly beta unlevered at its market D/E excl. operating leases (Comps col. M). Mean, not median: with three peers the median ignores DPZ's higher operating risk from its supply chain.
...

Sheet Comps
A1: Comparable companies - lease-consistent multiples, period-matched to MCD figures
A2: Source multiples from the Peers tab (Stock Analysis, 24-Sep-2026). Blue = inputs. Orange = changed after the guide review. Lavender = changed after the 25-Sep external feedback (see Model_Review rows 26+).
A4: Company | B4: Ticker | C4: Market cap ($bn) | D4: EV incl. leases ($bn) | E4: EV/EBITDA (source) | F4: LTM EBITDA ($bn) | G4: Operating lease liab. ($bn) | H4: EV excl. op. leases ($bn) | I4: EV/EBITDA lease-adjusted | J4: Net debt excl. leases ($bn) | K4: Debt / equity | L4: Levered beta | M4: Unlevered beta | N4: Forward P/E | O4: Debt / capital | P4: Operating-lease source
A6: =Peers!A5 -> Yum! Brands | B6: =Peers!B5 -> YUM | C6: =Peers!E5 -> 37.476958 | D6: =Peers!F5 -> 50.206958 | E6: =Peers!I5 -> 16.471995 | F6: =D6/E6 -> 3.0480192 | G6: 1.139 | H6: =D6-G6 -> 49.067958 | I6: =H6/F6 -> 16.09831 | J6: =H6-C6 -> 11.591 | K6: =MAX(0,J6/C6) -> 0.30928337 | L6: =Peers!J5 -> 0.55 | M6: =L6/(1+K6*(1-Forecast!$D$14)) -> 0.44310491 | N6: =Peers!H5 -> 21.570181 | O6: =K6/(1+K6) -> 0.2362234 | P6: YUM 10-Q 30-Jun-2026: non-current operating lease liabilities $1,139m (current portion sits in accrued liabilities, not separately retrieved).
A7: =Peers!A6 -> Restaurant Brands Intl. | B7: =Peers!B6 -> QSR | C7: =Peers!E6 -> 32.229119 | D7: =Peers!F6 -> 46.779119 | E7: =Peers!I6 -> 16.003383 | F7: =D7/E7 -> 2.9230769 | G7: 1.908 | H7: =D7-G7 -> 44.871119 | I7: =H7/F7 -> 15.350646 | J7: =H7-C7 -> 12.642 | K7: =MAX(0,J7/C7) -> 0.39225397 | L7: =Peers!J6 -> 0.53 | M7: =L7/(1+K7*(1-Forecast!$D$14)) -> 0.40583232 | N7: =Peers!H6 -> 16.713228 | O7: =K7/(1+K7) -> 0.28174024 | P7: QSR 10-Q 30-Jun-2026: operating lease liabilities, net of current portion $1,908m (current portion in other accrued liabilities).
A8: =Peers!A7 -> Starbucks | B8: =Peers!B7 -> SBUX | C8: =Peers!E7 -> 106.74107 | D8: =Peers!F7 -> 125.58107 | E8: =Peers!I7 -> 22.289195 | F8: =D8/E8 -> 5.6341682 | G8: 9 | H8: =D8-G8 -> 116.58107 | I8: =H8/F8 -> 20.691799 | J8: =H8-C8 -> 9.84 | K8: =MAX(0,J8/C8) -> 0.092185694 | L8: =Peers!J7 -> 0.97 | M8: =L8/(1+K8*(1-Forecast!$D$14)) -> 0.90493107 | N8: =Peers!H7 -> 31.850963 | O8: =K8/(1+K8) -> 0.08440478 | P8: ESTIMATE: SBUX had $10.3bn at Dec-2024 (current $1.45bn + LT $8.86bn); China retail operations divested in FQ3-2026. Exact Jun-2026 figure not retrieved - does not change the median.
A9: =Peers!A8 -> Chipotle Mexican Grill | B9: =Peers!B8 -> CMG | C9: =Peers!E8 -> 40.504274 | D9: =Peers!F8 -> 45.244274 | E9: =Peers!I8 -> 20.161588 | F9: =D9/E9 -> 2.2440828 | G9: 5.246 | H9: =D9-G9 -> 39.998274 | I9: =H9/F9 -> 17.823885 | J9: =H9-C9 -> -0.506 | K9: =MAX(0,J9/C9) -> 0 | L9: =Peers!J8 -> 0.94 | M9: =L9/(1+K9*(1-Forecast!$D$14)) -> 0.94 | N9: =Peers!H8 -> 25.621909 | O9: =K9/(1+K9) -> 0 | P9: CMG 10-Q 31-Mar-2026: current $310m + long-term $4,936m.
A10: =Peers!A9 -> Domino's Pizza | B10: =Peers!B9 -> DPZ | C10: =Peers!E9 -> 9.697481 | D10: =Peers!F9 -> 14.647481 | E10: =Peers!I9 -> 14.319997 | F10: =D10/E10 -> 1.022869 | G10: 0.239 | H10: =D10-G10 -> 14.408481 | I10: =H10/F10 -> 14.08634 | J10: =H10-C10 -> 4.711 | K10: =MAX(0,J10/C10) -> 0.48579626 | L10: =Peers!J9 -> 0.95 | M10: =L10/(1+K10*(1-Forecast!$D$14)) -> 0.68894443 | N10: =Peers!H9 -> 14.481967 | O10: =K10/(1+K10) -> 0.32696021 | P10: DPZ 14-Jun-2026: current $46m + long-term $193m (Stock Analysis balance sheet).
A11: Peer median | E11: =MEDIAN(E6:E10) -> 16.471995 | I11: =MEDIAN(I6:I10) -> 16.09831 | K11: =MEDIAN(K6:K10) -> 0.30928337 | L11: =MEDIAN(L6:L10) -> 0.94 | M11: =MEDIAN(M6:M10) -> 0.68894443 | N11: =MEDIAN(N6:N10) -> 21.570181 | O11: =MEDIAN(O6:O10) -> 0.2362234 | P11: Unlevering uses D/E excluding operating leases, consistent with not treating leases as capital (DCF guide Key Rule #5). One tax rate (22%) applied to all peers for simplicity.
A12: Peer 25th percentile | E12: =PERCENTILE(E6:E10,0.25) -> 16.003383 | I12: =PERCENTILE(I6:I10,0.25) -> 15.350646 | K12: =PERCENTILE(K6:K10,0.25) -> 0.092185694 | L12: =PERCENTILE(L6:L10,0.25) -> 0.55 | M12: =PERCENTILE(M6:M10,0.25) -> 0.44310491 | N12: =PERCENTILE(N6:N10,0.25) -> 16.713228 | O12: =PERCENTILE(O6:O10,0.25) -> 0.08440478
A13: Peer 75th percentile | E13: =PERCENTILE(E6:E10,0.75) -> 20.161588 | I13: =PERCENTILE(I6:I10,0.75) -> 17.823885 | K13: =PERCENTILE(K6:K10,0.75) -> 0.39225397 | L13: =PERCENTILE(L6:L10,0.75) -> 0.95 | M13: =PERCENTILE(M6:M10,0.75) -> 0.90493107 | N13: =PERCENTILE(N6:N10,0.75) -> 25.621909 | O13: =PERCENTILE(O6:O10,0.75) -> 0.28174024
A14: Franchise-heavy median (YUM, QSR, DPZ) - PRIMARY | E14: =MEDIAN(E6,E7,E10) -> 16.003383 | I14: =MEDIAN(I6,I7,I10) -> 15.350646 | K14: =MEDIAN(K6,K7,K10) -> 0.39225397 | L14: =MEDIAN(L6,L7,L10) -> 0.55 | M14: =MEDIAN(M6,M7,M10) -> 0.44310491 | N14: =MEDIAN(N6,N7,N10) -> 16.713228 | O14: =MEDIAN(O6,O7,O10) -> 0.28174024
A15: Franchise-heavy MEAN (YUM, QSR, DPZ) - used for the WACC beta | K15: =AVERAGE(K6,K7,K10) -> 0.39577787 | L15: =AVERAGE(L6,L7,L10) -> 0.67666667 | M15: =AVERAGE(M6,M7,M10) -> 0.51262722 | O15: =AVERAGE(O6,O7,O10) -> 0.28164129
A16: MCD METRICS (period-matched to each multiple)
A17: LTM operating income (GAAP) to 30-Jun-2026 | B17: $mm | C17: =Historical_5Y!G15+Reference_Data!I31-Reference_Data!H31 -> 12805 | P17: FY25 + H1-26 - H1-25 (multiples guide Key Rule #15). GAAP, because the source EBITDA for peers is unadjusted and MCD's restructuring has recurred for four years.
A18: H1-2026 D&A (cash flow statement) | B18: $mm | C18: 1131 | P18: MCD 10-Q Q2-2026, cash flow statement.
A19: H1-2025 D&A (cash flow statement) | B19: $mm | C19: 1064 | P19: MCD 10-Q Q2-2026, cash flow statement (prior-year column).
A20: LTM D&A | B20: $mm | C20: =Historical_5Y!G22+C18-C19 -> 2266
A21: LTM EBITDA (GAAP) | B21: $mm | C21: =C17+C20 -> 15071 | P21: Cross-check: Stock Analysis EV $223.68bn / 14.9x = $15.0bn.
A22: Weight of FY2026E in next twelve months | B22: % | C22: =(DATE(2026,12,31)-Market_WACC!B7)/365 -> 0.26849315 | P22: (31-Dec-2026 - price date) / 365.
A23: NTM diluted EPS (adjusted) | B23: $/sh | C23: =C22*Forecast!D31+(1-C22)*Forecast!E31 -> 13.347176 | P23: Calendarised: w x FY26E + (1 - w) x FY27E (multiples guide Key Rule #16). Adjusted to match consensus-based forward P/E.
A24: Net debt (fair-value debt less cash, 30-Jun-2026) | B24: $mm | C24: =DCF!B13 -> 37478 | P24: DCF tab - same bridge as the DCF. Leases excluded because EBITDA is after rent (lease-adjusted multiples above).
A25: Diluted shares | B25: mm | C25: =WACC!B11 -> 709.64 | P25: WACC tab (basic + treasury-stock dilution).
A27: IMPLIED VALUE PER SHARE - PRIMARY SET: FRANCHISE-HEAVY PEERS (YUM, QSR, DPZ)
A28: Method | C28: Low (min) | D28: Median | E28: High (max) | F28: Weight | P28: Note
A29: Forward P/E x NTM EPS | C29: =MIN(N6,N7,N10)*$C$23 -> 193.29336 | D29: =N14*$C$23 -> 223.07439 | E29: =MAX(N6,N7,N10)*$C$23 -> 287.901 | F29: 0.5 | P29: REVISED (feedback): franchise-heavy peer forward P/E (min / median / max of YUM, QSR, DPZ) x MCD NTM EPS. SBUX and CMG are company-operated and priced on faster growth, so they no longer set the target (all-five result kept in row 34).
A30: LTM EV/EBITDA (lease-adjusted) x LTM EBITDA | C30: =(MIN(I6,I7,I10)*$C$21-$C$24)/$C$25 -> 246.34636 | D30: =(I14*$C$21-$C$24)/$C$25 -> 273.1971 | E30: =(MAX(I6,I7,I10)*$C$21-$C$24)/$C$25 -> 289.07563 | F30: =1-F29 -> 0.5 | P30: REVISED (feedback): franchise-heavy peers only. Trailing multiple on MCD LTM EBITDA (period-matched); EV excludes operating leases to pair with post-rent EBITDA (multiples guide Key Rules #8, #9).
A31: Comps value per share (weighted) - used in the target | C31: =C29*$F$29+C30*$F$30 -> 219.81986 | D31: =D29*$F$29+D30*$F$30 -> 248.13575 | E31: =E29*$F$29+E30*$F$30 -> 288.48831 | P31: Why 50/50 (round 4): EV/EBITDA is capital-structure neutral, which matters because the franchise-heavy peers carry more debt than MCD, but it ignores D&A and capex, and MCD owns much of its real estate, which flatters it on EBITDA. Forward P/E captures D&A, interest and tax and is forward-looking, but is distorted by the peers' higher leverage. The biases run in opposite directions and neither clearly dominates, so each gets half; the DCF (60%) remains the anchor.
A33: MEMO / CROSS-CHECKS (not used in the target)
A34: All five peers (previous primary set): 25th / median / 75th | C34: =(N12*$C$23)*$F$29+((I12*$C$21-$C$24)/$C$25)*$F$30 -> 248.13575 | D34: =(N11*$C$23)*$F$29+((I11*$C$21-$C$24)/$C$25)*$F$30 -> 288.48831 | E34: =(N13*$C$23)*$F$29+((I13*$C$21-$C$24)/$C$25)*$F$30 -> 333.85135 | P34: What the target used before the feedback review (median $292.69). Shows how much company-operated SBUX and CMG lift the peer set.
A35: Previous method: source EV/EBITDA x NTM EBITDA | D35: =(E11*(C22*Forecast!D25+(1-C22)*Forecast!E25)-(C24+DCF!B14))/C25 -> 301.46148 | P35: What the model did before the review: trailing multiple on forward EBITDA and lease-inclusive EV - mismatched on both period and leases.
A36: MCD at current price: forward P/E (NTM) | D36: =Market_WACC!B6/C23 -> 17.758063 | P36: vs franchise-heavy median in N14 (all-peer median in N11).
A37: MCD at current price: LTM EV/EBITDA (excl. op. leases) | D37: =(WACC!B12+C24)/C21 -> 13.647195 | P37: vs franchise-heavy median in I14 (all-peer median in I11).
A39: PEER GROWTH & BUSINESS MODEL - why the franchise-heavy set is primary (added after feedback)
A40: Company | B40: Ticker | C40: Forward P/E | D40: Trailing P/E | E40: Implied NTM EPS growth | F40: EV/EBITDA (lease-adj.) | G40: Primary set? | P40: Business model / note
A41: =A6 -> Yum! Brands | B41: =B6 -> YUM | C41: =N6 -> 21.570181 | D41: =Peers!G5 -> 17.443283 | E41: =D41/C41-1 -> -0.1913242 | F41: =I6 -> 16.09831 | G41: Yes | P41: Franchise-heavy: ~97% franchised at end-2025 (beta note, citing YUM 2025 10-K). Implied growth understated: trailing EPS flattered by a one-off tax benefit.
A42: =A7 -> Restaurant Brands Intl. | B42: =B7 -> QSR | C42: =N7 -> 16.713228 | D42: =Peers!G6 -> 19.12769 | E42: =D42/C42-1 -> 0.14446418 | F42: =I7 -> 15.350646 | G42: Yes | P42: Franchise-heavy (Burger King, Tim Hortons, Popeyes, Firehouse); predominantly franchised.
A43: =A8 -> Starbucks | B43: =B8 -> SBUX | C43: =N8 -> 31.850963 | D43: =Peers!G7 -> 53.868676 | E43: =D43/C43-1 -> 0.69127307 | F43: =I8 -> 20.691799 | G43: No | P43: Mostly company-operated; 7,991 China stores moved to licensed in 2026 (beta note) but still far less franchise-intensive. Implied growth overstated: trailing EPS depressed by restructuring.
A44: =A9 -> Chipotle Mexican Grill | B44: =B9 -> CMG | C44: =N9 -> 25.621909 | D44: =Peers!G8 -> 30.122384 | E44: =D44/C44-1 -> 0.17564948 | F44: =I9 -> 17.823885 | G44: No | P44: Almost entirely company-operated.
A45: =A10 -> Domino's Pizza | B45: =B10 -> DPZ | C45: =N10 -> 14.481967 | D45: =Peers!G9 -> 16.597422 | E45: =D45/C45-1 -> 0.14607509 | F45: =I10 -> 14.08634 | G45: Yes | P45: ~99% franchised, but runs a large supply chain (~$3.0bn of ~$4.9bn 2025 revenue, beta note): explains its higher beta.
...

Sheet Peers
A1: Peer multiples - quick-service & fast-casual restaurants
A2: Source: Stock Analysis (S&P Global Market Intelligence). REVISED round 5: every price is the official 24-Sep-2026 close; peer multiples are the source snapshot (rows 29-33) rescaled to that close. Lavender = changed after the feedback reviews.
A4: Company | B4: Ticker | C4: Price ($) | D4: Price as of | E4: Market cap ($bn) | F4: EV ($bn) | G4: P/E trailing | H4: P/E forward | I4: EV/EBITDA trailing | J4: Beta (5Y) | K4: Note
A5: Yum! Brands | B5: YUM | C5: 137.34 | D5: 24-Sep close | E5: =E29*C5/C29 -> 37.476958 | F5: =F29+(E5-E29) -> 50.206958 | G5: =G29*C5/C29 -> 17.443283 | H5: =H29*C5/C29 -> 21.570181 | I5: =F5/(F29/I29) -> 16.471995 | J5: =J29 -> 0.55 | K5: Trailing P/E flattered by a one-off tax benefit (negative TTM tax); use forward P/E
A6: Restaurant Brands Intl. | B6: QSR | C6: 70.91 | D6: 24-Sep close | E6: =E30*C6/C30 -> 32.229119 | F6: =F30+(E6-E30) -> 46.779119 | G6: =G30*C6/C30 -> 19.12769 | H6: =H30*C6/C30 -> 16.713228 | I6: =F6/(F30/I30) -> 16.003383 | J6: =J30 -> 0.53 | K6: Market cap includes exchangeable LP units (454.5m shares)
A7: Starbucks | B7: SBUX | C7: 93.65 | D7: 24-Sep close | E7: =E31*C7/C31 -> 106.74107 | F7: =F31+(E7-E31) -> 125.58107 | G7: =G31*C7/C31 -> 53.868676 | H7: =H31*C7/C31 -> 31.850963 | I7: =F7/(F31/I31) -> 22.289195 | J7: =J31 -> 0.97 | K7: Trailing earnings depressed by turnaround/restructuring costs
A8: Chipotle Mexican Grill | B8: CMG | C8: 32.01 | D8: 24-Sep close | E8: =E32*C8/C32 -> 40.504274 | F8: =F32+(E8-E32) -> 45.244274 | G8: =G32*C8/C32 -> 30.122384 | H8: =H32*C8/C32 -> 25.621909 | I8: =F8/(F32/I32) -> 20.161588 | J8: =J32 -> 0.94 | K8: Company-operated model, net debt mostly leases; post 50:1 split
A9: Domino's Pizza | B9: DPZ | C9: 293.03 | D9: 24-Sep close | E9: =E33*C9/C33 -> 9.697481 | F9: =F33+(E9-E33) -> 14.647481 | G9: =G33*C9/C33 -> 16.597422 | H9: =H33*C9/C33 -> 14.481967 | I9: =F9/(F33/I33) -> 14.319997 | J9: =J33 -> 0.95 | K9: Heavily franchised, highly levered
A10: Peer median | E10: =MEDIAN(E5:E9) -> 37.476958 | F10: =MEDIAN(F5:F9) -> 46.779119 | G10: =MEDIAN(G5:G9) -> 19.12769 | H10: =MEDIAN(H5:H9) -> 21.570181 | I10: =MEDIAN(I5:I9) -> 16.471995 | J10: =MEDIAN(J5:J9) -> 0.94
A11: Peer mean | E11: =AVERAGE(E5:E9) -> 45.329781 | F11: =AVERAGE(F5:F9) -> 56.491781 | G11: =AVERAGE(G5:G9) -> 27.431891 | H11: =AVERAGE(H5:H9) -> 22.047649 | I11: =AVERAGE(I5:I9) -> 17.849232 | J11: =AVERAGE(J5:J9) -> 0.788
A12: Franchise-heavy median (YUM, QSR, DPZ) - primary set | E12: =MEDIAN(E5,E6,E9) -> 32.229119 | F12: =MEDIAN(F5,F6,F9) -> 46.779119 | G12: =MEDIAN(G5,G6,G9) -> 17.443283 | H12: =MEDIAN(H5,H6,H9) -> 16.713228 | I12: =MEDIAN(I5,I6,I9) -> 16.003383 | J12: =MEDIAN(J5,J6,J9) -> 0.55
A13: McDonald's (24-Sep close) | B13: MCD | C13: =Market_WACC!B6 -> 237.02 | D13: 24-Sep close | E13: =Market_WACC!B9/1000 -> 167.72483 | F13: =F24+(E13-E24) -> 221.50483 | G13: =G24*C13/C24 -> 19.112446 | H13: =H24*C13/C24 -> 17.799453 | I13: =F13/(F24/I24) -> 14.755106 | J13: =Market_WACC!B10 -> 0.41 | K13: REVISED (feedback): price links to Market_WACC (24-Sep close). Source multiples were captured at $240.09 (row 24): P/E rescaled by price; EV moved by the change in market cap; EBITDA unchanged.
A14: MCD premium / (discount) vs all-peer median | G14: =G13/G10-1 -> -0.00079697634 | H14: =H13/H10-1 -> -0.17481207 | I14: =I13/I10-1 -> -0.10423083
A15: MCD premium / (discount) vs franchise-heavy median | G15: =G13/G12-1 -> 0.095690875 | H15: =H13/H12-1 -> 0.064991932 | I15: =I13/I12-1 -> -0.078000847
A16: Reading this table:
A17: - Forward P/E is the cleanest comparison: trailing P/E is distorted for YUM (tax benefit) and SBUX (restructuring).
A18: - At the close MCD sits ~19% below the all-peer median on forward P/E (row 14), but only slightly above the franchise-heavy median on P/E and below it on EV/EBITDA (row 15): on the closest business models MCD looks fairly priced, not cheap.
A19: - Business models differ: CMG and SBUX are mostly company-operated (lower margins, higher growth); YUM, QSR and DPZ are franchise-heavy like MCD, so they are the primary set on Comps from this revision.
A20: - Timestamps: every price (peers and MCD) is the official 24-Sep close (round 5); multiples are rescaled from the 23-24 Sep source snapshot, holding EPS, EBITDA and net debt constant.
A21: - The task suggested Koyfin or Yahoo Finance; these came from Stock Analysis because it publishes all the fields on one page.
A23: MEMO: MCD SOURCE SNAPSHOT AS CAPTURED 24-SEP 9:56AM ET (rescaled to the close in row 13)
A24: McDonald's - source snapshot | B24: MCD | C24: =Market_WACC!B12 -> 240.09 | D24: 24-Sep 9:56am | E24: 169.9 | F24: 223.68 | G24: 19.36 | H24: 18.03 | I24: 14.9 | K24: Stock Analysis statistics page as captured (EV includes leases). Kept so the rescaling in row 13 is traceable.
A27: MEMO: PEER SOURCE SNAPSHOT AS CAPTURED (23-Sep close / 24-Sep morning) - rescaled to the 24-Sep close in rows 5-9
A28: Company | B28: Ticker | C28: Price ($) | D28: Captured | E28: Market cap ($bn) | F28: EV ($bn) | G28: P/E trailing | H28: P/E forward | I28: EV/EBITDA trailing | J28: Beta (5Y)
A29: =A5 -> Yum! Brands | B29: =B5 -> YUM | C29: 139.44 | D29: 24-Sep 9:49am | E29: 38.05 | F29: 50.78 | G29: 17.71 | H29: 21.9 | I29: 16.66 | J29: 0.55 | K29: Stock Analysis statistics pages as captured 23-24 Sep. Rows 5-9 take the official 24-Sep closes from the Stock Analysis history pages (S&P Global): P/E rescaled by price; EV moved by the change in market cap; EBITDA, net debt and beta unchanged.
A30: =A6 -> Restaurant Brands Intl. | B30: =B6 -> QSR | C30: 71.66 | D30: 23-Sep close | E30: 32.57 | F30: 47.12 | G30: 19.33 | H30: 16.89 | I30: 16.12 | J30: 0.53
A31: =A7 -> Starbucks | B31: =B7 -> SBUX | C31: 94 | D31: 24-Sep 9:51am | E31: 107.14 | F31: 125.98 | G31: 54.07 | H31: 31.97 | I31: 22.36 | J31: 0.97
A32: =A8 -> Chipotle Mexican Grill | B32: =B8 -> CMG | C32: 32.22 | D32: 24-Sep 9:51am | E32: 40.77 | F32: 45.51 | G32: 30.32 | H32: 25.79 | I32: 20.28 | J32: 0.94
A33: =A9 -> Domino's Pizza | B33: =B9 -> DPZ | C33: 296.43 | D33: 23-Sep close | E33: 9.81 | F33: 14.76 | G33: 16.79 | H33: 14.65 | I33: 14.43 | J33: 0.95

Sheet Historical_5Y
A1: McDonald's - five-year annual history (FY2021-FY2025)
A2: Blue = figure from the 10-Ks (source in column I). Black = formula. $ millions unless stated. Fiscal year ends 31 December.
A4: Line item | B4: Unit | C4: FY2021 | D4: FY2022 | E4: FY2023 | F4: FY2024 | G4: FY2025 | H4: CAGR 21-25 | I4: Source
A5: REVENUE
A6: Revenues from franchised restaurants | B6: $mm | C6: 13085 | D6: 14106 | E6: 15437 | F6: 15715 | G6: 16548 | H6: =IFERROR((G6/C6)^(1/4)-1,"") -> 0.060456715 | I6: 10-K FY2022 (SEC) p.13; 10-K FY2025 (project file) p.39
A7: Sales by company-operated restaurants | B7: $mm | C7: 9787 | D7: 8748 | E7: 9742 | F7: 9782 | G7: 9690 | H7: =IFERROR((G7/C7)^(1/4)-1,"") -> -0.0024870393 | I7: 10-K FY2022 (SEC) p.11; 10-K FY2025 (project file) p.39
A8: Other revenues | B8: $mm | C8: 351 | D8: 329 | E8: 316 | F8: 423 | G8: 647 | H8: =IFERROR((G8/C8)^(1/4)-1,"") -> 0.16519682 | I8: 10-K FY2022 (SEC) p.11; 10-K FY2025 (project file) p.39
A9: Total revenues | B9: $mm | C9: =SUM(C6:C8) -> 23223 | D9: =SUM(D6:D8) -> 23183 | E9: =SUM(E6:E8) -> 25495 | F9: =SUM(F6:F8) -> 25920 | G9: =SUM(G6:G8) -> 26885 | H9: =IFERROR((G9/C9)^(1/4)-1,"") -> 0.037284599 | I9: Formula
A10: Franchised % of total revenue | B10: % | C10: =C6/C9 -> 0.56345003 | D10: =D6/D9 -> 0.6084631 | E10: =E6/E9 -> 0.60549127 | F10: =F6/F9 -> 0.60628858 | G10: =G6/G9 -> 0.61551051 | I10: Formula
A11: Company-operated % of total revenue | B11: % | C11: =C7/C9 -> 0.42143565 | D11: =D7/D9 -> 0.37734547 | E11: =E7/E9 -> 0.38211414 | F11: =F7/F9 -> 0.37739198 | G11: =G7/G9 -> 0.36042403 | I11: Formula
A12: Total revenue growth YoY | B12: % | D12: =D9/C9-1 -> -0.0017224303 | E12: =E9/D9-1 -> 0.099728249 | F12: =F9/E9-1 -> 0.016669935 | G12: =G9/F9-1 -> 0.037229938 | I12: Formula
A14: PROFIT & PER SHARE
A15: Operating income (GAAP) | B15: $mm | C15: 10356 | D15: 9371 | E15: 11647 | F15: 11712 | G15: 12393 | H15: =IFERROR((G15/C15)^(1/4)-1,"") -> 0.045914303 | I15: 10-K FY2022 (SEC) p.11; 10-K FY2025 (project file) p.39
A16: Operating income (non-GAAP, company) | B16: $mm | C16: 10071 | D16: 10381 | F16: 12003 | G16: 12621 | I16: 10-K FY2022 (SEC) p.17; 10-K FY2025 (project file) p.18 (FY23 not retrieved)
A17: Operating margin (GAAP) | B17: % | C17: =C15/C9 -> 0.44593722 | D17: =D15/D9 -> 0.40421861 | E17: =E15/E9 -> 0.45683467 | F17: =F15/F9 -> 0.45185185 | G17: =G15/G9 -> 0.46096336 | I17: Formula
